Workbook

Sheet 1. README
A1: Aadesh AI Financial Model v3 · April 27, 2026 · Launch pricing LOCKED
A4: Purpose | B4: Real unit economics, break-even, and survival runway for Aadesh AI
A5: Built by | B5: Claude (CTO) from data in MASTER_CONTEXT.md and AADESH_AI_BLUEPRINT_v9_2_2.md
A6: Built on | B6: April 27, 2026 — v3 with launch pricing locked (Starter/Regular/Pro)
A8: COLOR CODING
B9: Blue text | C9: Hardcoded inputs you can change
B10: Black text | C10: Formulas — do not edit
B11: Green text | C11: Pulls from another sheet — do not edit
B12: Red text | C12: Warning or external reference
B13: Yellow background | C13: Key assumption — verify regularly
A15: SHEETS IN THIS WORKBOOK
A16: Sheet 2 | B16: Inputs & Assumptions | C16: Single source of truth — change values here
A17: Sheet 3 | B17: API Cost Reality | C17: Real testing spend → per-order cost derivation
A18: Sheet 4 | B18: Fixed Monthly Costs | C18: VPS, Supabase, domain, monitoring
A19: Sheet 5 | B19: Per-Order Unit Economics | C19: For each pack: revenue → costs → real margin
A20: Sheet 6 | B20: Free Trial Burn | C20: Cost of free trials at various conversion rates
A21: Sheet 7 | B21: 12-Month P&L | C21: Three scenarios: conservative, base, upside
A22: Sheet 8 | B22: Break-Even Analysis | C22: Users needed at different cost levels
A23: Sheet 9 | B23: CAC + LTV | C23: Founder time per user; transfer impact
A24: Sheet 10 | B24: Pricing Decisions | C24: Should pricing change? Math says...
A25: Sheet 11 | B25: CRITICAL FINDINGS | C25: Issues uncovered while building this model
A26: Sheet 12 | B26: Live Cost Tracker | C26: Empty template — populate with real production orders
A27: Sheet 13 | B27: Office Plan Economics | C27: Three office-tier plans for shared-login scenarios
A29: HOW TO USE
A30: Step 1 | B30: Go to Sheet 2 (Inputs) | C30: Adjust any blue cell to test scenarios
A31: Step 2 | B31: All other sheets recalculate automatically
A32: Step 3 | B32: Read Sheet 11 first if you want the surprises

Sheet 2. Inputs
A1: INPUTS & ASSUMPTIONS · Change values in BLUE only
A2: All other sheets pull from this sheet. Edit any blue cell to test scenarios.
A4: § ANTHROPIC API COSTS (April 2026 actual rates)
A5: Input tokens | B5: $/M | C5: 3 | D5: Source: console.anthropic.com
A6: Output tokens | B6: $/M | C6: 15 | D6: Source: console.anthropic.com
A7: Cache write (first time) | B7: $/M | C7: 3.75 | D7: 25% premium over input
A8: Cache read (cache hit) | B8: $/M | C8: 0.3 | D8: 90% discount on cached input
A9: USD to INR exchange rate | B9: ₹/USD | C9: 84 | D9: Approximate April 2026
A10: India tax markup | B10: % | C10: 0.21 | D10: 2-3% forex + 18% GST on imports
A12: § TYPICAL ORDER TOKEN USAGE
A13: Step 1 — PDF Vision input tokens | B13: tokens | C13: 35000 | D13: 20-page CamScanner PDF average
A14: Step 1 — PDF Vision output tokens | B14: tokens | C14: 700
A15: Step 2 — Generation input (NEW per order) | B15: tokens | C15: 2000 | D15: Case details + officer answers
A16: Step 2 — Generation cache READ (refs) | B16: tokens | C16: 50000 | D16: 5 reference orders cached
A17: Step 2 — Generation cache READ (sysprompt) | B17: tokens | C17: 18000 | D17: V3.2.6 system prompt cached
A18: Step 2 — Generation output tokens | B18: tokens | C18: 8000 | D18: Full Kannada order ~14 tokens/word
A19: Step 3 — Self-audit input tokens | B19: tokens | C19: 9000
A20: Step 3 — Self-audit output tokens | B20: tokens | C20: 1000
A22: § OPERATIONAL ASSUMPTIONS
A23: Cache hit rate (% orders with hot cache) | B23: % | C23: 0.5 | D23: 50% sporadic, 50% in-burst
A24: Self-audit failure rate (regen needed) | B24: % | C24: 0.25 | D24: Buffer for regeneration
A25: Failed-generation rate (refunded, no revenue) | B25: % | C25: 0.05 | D25: Buffer for failures
A27: § MONTHLY FIXED COSTS (₹)
A28: DigitalOcean Bangalore VPS | B28: ₹/month | C28: 1250 | D28: 1GB plan; upgrade at user 4
A29: Supabase Mumbai | B29: ₹/month | C29: 0 | D29: Free tier; ₹2,100 at upgrade
A30: Domain (aadesh-ai.in) | B30: ₹/month | C30: 100 | D30: ₹1,200/year amortised
A31: Email / SMS / monitoring | B31: ₹/month | C31: 500 | D31: UptimeRobot, transactional
A32: Backups / logging | B32: ₹/month | C32: 500 | D32: DO Spaces backup
A33: GitHub Actions / dev tools | B33: ₹/month | C33: 0 | D33: Free tier
A34: Founder tools (Claude Pro, etc.) | B34: ₹/month | C34: 1700 | D34: Claude Pro ₹1,700
A35: Misc / contingency | B35: ₹/month | C35: 950 | D35: Domain renewal, fees, etc.
A37: § PRICING (LOCKED LAUNCH PRICING — April 27, 2026)
A38: Starter — Price | B38: ₹ | C38: 999 | D38: LOCKED ✓ Launch pricing — replaces Pack A
A39: Starter — Credits | B39: orders | C39: 3 | D39: 3 orders
A40: Regular — Price | B40: ₹ | C40: 1499 | D40: LOCKED ✓ Launch pricing — replaces Pack B
A41: Regular — Credits | B41: orders | C41: 5 | D41: 5 orders
A42: Pro — Price | B42: ₹ | C42: 2499 | D42: LOCKED ✓ Launch pricing — replaces Pack C
A43: Pro — Credits | B43: orders | C43: 10 | D43: 10 orders
A44: Bulk (HIDDEN at launch) — Price | B44: ₹ | C44: 4999 | D44: ⏳ Hidden — unlock after 20-30 paid orders
A45: Bulk (HIDDEN at launch) — Credits | B45: orders | C45: 25 | D45: 25 orders
...

Sheet 3. API Cost Reality
A1: API COST REALITY · Per-order cost derived from real Anthropic rates
A3: A. Actual testing spend to date (from MASTER_CONTEXT.md)
A4: Event | B4: Cost (USD) | C4: Cost (₹) | D4: Notes
A5: Starting balance | B5: 50 | C5: =B5*'2. Inputs'!$C$9 -> 4200 | D5: Free credit
A6: Thinking-mode accident (Apr 11) | B6: -11.15 | C6: =B6*'2. Inputs'!$C$9 -> -936.6 | D6: D7 decision: never use thinking mode
A7: V3.2.3-V3.2.6 testing | B7: -12.3 | C7: =B7*'2. Inputs'!$C$9 -> -1033.2 | D7: Synthetic test runs
A8: Current balance | B8: 26.55 | C8: =B8*'2. Inputs'!$C$9 -> 2230.2 | D8: As of MASTER_CONTEXT date
A9: TOTAL TESTING SPEND | B9: 23.45 | C9: =B9*'2. Inputs'!$C$9 -> 1969.8 | D9: $50 - $26.55
A12: B. Per-order cost calculation (from token usage assumptions)
A13: Step | B13: What happens | C13: Cost (USD) | D13: Cost (₹ pre-tax) | E13: Cost (₹ with India tax) | F13: Notes
A14: Step 1 | B14: PDF Vision read (avg 20 pages) | C14: =('2. Inputs'!$C$13*'2. Inputs'!$C$5 + '2. Inputs'!$C$14*'2. Inputs'!$C$6)/1000000 -> 0.1155 | D14: =C14*'2. Inputs'!$C$9 -> 9.702 | E14: =D14*(1+'2. Inputs'!$C$10) -> 11.73942 | F14: No cache benefit — different PDF each time
A15: Step 2 — cache HOT | B15: Generation with refs+sysprompt cached | C15: =('2. Inputs'!$C$15*'2. Inputs'!$C$5 + ('2. Inputs'!$C$16+'2. Inputs'!$C$17)*'2. Inputs'!$C$8 + '2. Inputs'!$C$18*'2. Inputs'!$C$6)/1000000 -> 0.1464 | D15: =C15*'2. Inputs'!$C$9 -> 12.2976 | E15: =D15*(1+'2. Inputs'!$C$10) -> 14.880096 | F15: 90% discount on cached tokens
A16: Step 2 — cache COLD | B16: Generation, refs+sysprompt cache write | C16: =('2. Inputs'!$C$15*'2. Inputs'!$C$5 + ('2. Inputs'!$C$16+'2. Inputs'!$C$17)*'2. Inputs'!$C$7 + '2. Inputs'!$C$18*'2. Inputs'!$C$6)/1000000 -> 0.381 | D16: =C16*'2. Inputs'!$C$9 -> 32.004 | E16: =D16*(1+'2. Inputs'!$C$10) -> 38.72484 | F16: 25% premium on first write of cache
A17: Step 3 | B17: Self-audit scoring | C17: =('2. Inputs'!$C$19*'2. Inputs'!$C$5 + '2. Inputs'!$C$20*'2. Inputs'!$C$6)/1000000 -> 0.042 | D17: =C17*'2. Inputs'!$C$9 -> 3.528 | E17: =D17*(1+'2. Inputs'!$C$10) -> 4.26888 | F17: No cache benefit
A19: PER-ORDER (cache HOT — best case) | C19: =C14+C15+C17 -> 0.3039 | D19: =D14+D15+D17 -> 25.5276 | E19: =E14+E15+E17 -> 30.888396 | F19: Officer in burst session
A20: PER-ORDER (cache COLD — first order) | C20: =C14+C16+C17 -> 0.5385 | D20: =D14+D16+D17 -> 45.234 | E20: =E14+E16+E17 -> 54.73314 | F20: First order of session, cache write
A21: PER-ORDER (BLENDED — realistic) | C21: =E19*'2. Inputs'!$C$23/(1+'2. Inputs'!$C$10) + E20*(1-'2. Inputs'!$C$23)/(1+'2. Inputs'!$C$10) -> 35.3808 | D21: =C21*'2. Inputs'!$C$9 -> 2971.9872 | E21: =E19*'2. Inputs'!$C$23 + E20*(1-'2. Inputs'!$C$23) -> 42.810768 | F21: Weighted by cache hit rate
A22: PER-ORDER (with regen + failure buffer) | E22: =E21*(1+'2. Inputs'!$C$24)/(1-'2. Inputs'!$C$25) -> 56.329958 | F22: What we should budget against revenue
A25: C. Real testing spend ÷ test orders = real per-test cost
A26: Total testing spend (USD) | B26: =B9 -> 23.45
A27: Number of test orders generated | B27: 29 | C27: From handbook v3.2 — "29 test orders generated"
A28: Implied real cost per test (USD) | B28: =B26/B27 -> 0.80862069
A29: Implied real cost per test (₹) | B29: =B28*'2. Inputs'!$C$9*(1+'2. Inputs'!$C$10) -> 82.188207
A30: Production target per order (this model) | B30: =E22 -> 56.329958
A31: Why production should be cheaper | B31: =IF(B29>B30,B29-B30,0) -> 25.858249 | C31: Production has cache hits + no thinking mode
A33: D. Sensitivity: what if Anthropic doubles prices?
A34: Scenario | B34: Multiplier | C34: Per-order cost (₹) | D34: Δ vs base | E34: Implication
A35: Base case (current rates) | B35: 1 | C35: =E$22*B35 -> 56.329958 | D35: =C35-E$22 -> 0 | E35: Current operations
A36: Anthropic +25% (forex hit) | B36: 1.25 | C36: =E$22*B36 -> 70.412447 | D36: =C36-E$22 -> 14.082489 | E36: Margin compresses
A37: Anthropic +50% (model upgrade) | B37: 1.5 | C37: =E$22*B37 -> 84.494937 | D37: =C37-E$22 -> 28.164979 | E37: May need to raise prices
A38: Anthropic +100% (worst case) | B38: 2 | C38: =E$22*B38 -> 112.65992 | D38: =C38-E$22 -> 56.329958 | E38: Pricing review required
A39: Anthropic +50% AND we switch to Sonnet 5 | B39: 1 | C39: =E$22*B39 -> 56.329958 | D39: =C39-E$22 -> 0 | E39: Newer model could be cheaper

Sheet 4. Fixed Costs
A1: FIXED MONTHLY COSTS · Now vs at scale
A3: Cost Item | B3: Today (₹/month) | C3: At 50 users (₹/month) | D3: At 200 users (₹/month) | E3: Notes
A4: DigitalOcean VPS | B4: ='2. Inputs'!$C$28 -> 1250 | C4: 5000 | D4: 12000 | E4: 1GB now → 4GB at user 4 → 16GB at scale
A5: Supabase | B5: ='2. Inputs'!$C$29 -> 0 | C5: 2100 | D5: 4200 | E5: Free tier → Pro at 3+ users
A6: Domain | B6: ='2. Inputs'!$C$30 -> 100 | C6: ='2. Inputs'!$C$30 -> 100 | D6: ='2. Inputs'!$C$30 -> 100 | E6: ₹1,200/year amortised
A7: Email / SMS / monitoring | B7: ='2. Inputs'!$C$31 -> 500 | C7: 2000 | D7: 5000 | E7: Volume scales
A8: Backups / logging | B8: ='2. Inputs'!$C$32 -> 500 | C8: 2000 | D8: 5000 | E8: DO Spaces grows with data
A9: GitHub Actions / dev tools | B9: ='2. Inputs'!$C$33 -> 0 | C9: 0 | D9: 0 | E9: Free tier OK
A10: Founder tools | B10: ='2. Inputs'!$C$34 -> 1700 | C10: 1700 | D10: 1700 | E10: Claude Pro
A11: Misc / contingency | B11: ='2. Inputs'!$C$35 -> 950 | C11: 2000 | D11: 5000 | E11: Domain renewals, fees
A12: TOTAL FIXED MONTHLY COST | B12: =SUM(B4:B11) -> 5000 | C12: =SUM(C4:C11) -> 14900 | D12: =SUM(D4:D11) -> 33000
A14: Fixed cost allocation per order at different volumes
A15: Volume scenario | B15: Orders/month | C15: Total fixed cost | D15: ₹/order allocation
A16: Today (10 orders) | B16: 10 | C16: =B12 -> 5000 | D16: =C16/B16 -> 500
A17: 30 orders/month | B17: 30 | C17: =B12 -> 5000 | D17: =C17/B17 -> 166.66667
A18: 100 orders/month (~10 users) | B18: 100 | C18: =B12 -> 5000 | D18: =C18/B18 -> 50
A19: 500 orders/month (~50 users) | B19: 500 | C19: =C12 -> 14900 | D19: =C19/B19 -> 29.8
A20: 2000 orders/month (~200 users) | B20: 2000 | C20: =D12 -> 33000 | D20: =C20/B20 -> 16.5

Sheet 5. Unit Economics
A1: PER-ORDER UNIT ECONOMICS · Real margin per pack after all costs
A3: Component | B3: Starter (₹999) | C3: Regular (₹1,499) | D3: Pro (₹2,499) | E3: Bulk ⏳ HIDDEN (₹4,999) | F3: Formula / Notes
A4: Pack price (gross) | B4: ='2. Inputs'!$C$38 -> 999 | C4: ='2. Inputs'!$C$40 -> 1499 | D4: ='2. Inputs'!$C$42 -> 2499 | E4: ='2. Inputs'!$C$44 -> 4999 | F4: From Inputs sheet (live Razorpay)
A5: Credits per pack | B5: ='2. Inputs'!$C$39 -> 3 | C5: ='2. Inputs'!$C$41 -> 5 | D5: ='2. Inputs'!$C$43 -> 10 | E5: ='2. Inputs'!$C$45 -> 25 | F5: Orders per pack
A6: User price per order | B6: =B4/B5 -> 333 | C6: =C4/C5 -> 299.8 | D6: =D4/D5 -> 249.9 | E6: =E4/E5 -> 199.96 | F6: price / credits
A7: Less: GST (if registered) | B7: =-B6*'2. Inputs'!$C$50/(1+'2. Inputs'!$C$50)*'2. Inputs'!$C$49 -> 0 | C7: =-C6*'2. Inputs'!$C$50/(1+'2. Inputs'!$C$50)*'2. Inputs'!$C$49 -> 0 | D7: =-D6*'2. Inputs'!$C$50/(1+'2. Inputs'!$C$50)*'2. Inputs'!$C$49 -> 0 | E7: =-E6*'2. Inputs'!$C$50/(1+'2. Inputs'!$C$50)*'2. Inputs'!$C$49 -> 0 | F7: GST is included in price; remit to govt
A8: Less: Razorpay fee (3.53%) | B8: =-B6*'2. Inputs'!$C$48 -> -11.7549 | C8: =-C6*'2. Inputs'!$C$48 -> -10.58294 | D8: =-D6*'2. Inputs'!$C$48 -> -8.82147 | E8: =-E6*'2. Inputs'!$C$48 -> -7.058588 | F8: Per-transaction allocation
A9: Less: AI cost per order | B9: =-'3. API Cost Reality'!$E$22 -> -56.329958 | C9: =-'3. API Cost Reality'!$E$22 -> -56.329958 | D9: =-'3. API Cost Reality'!$E$22 -> -56.329958 | E9: =-'3. API Cost Reality'!$E$22 -> -56.329958 | F9: Blended Sonnet 4.6 with regen buffer
A10: Less: Fixed-cost allocation | B10: =-'4. Fixed Costs'!$B$12/100 -> -50 | C10: =-'4. Fixed Costs'!$B$12/100 -> -50 | D10: =-'4. Fixed Costs'!$B$12/100 -> -50 | E10: =-'4. Fixed Costs'!$B$12/100 -> -50 | F10: Spread over 100 orders/month baseline
A11: Less: Failed-generation buffer | B11: =-'3. API Cost Reality'!$E$21*'2. Inputs'!$C$25 -> -2.1405384 | C11: =-'3. API Cost Reality'!$E$21*'2. Inputs'!$C$25 -> -2.1405384 | D11: =-'3. API Cost Reality'!$E$21*'2. Inputs'!$C$25 -> -2.1405384 | E11: =-'3. API Cost Reality'!$E$21*'2. Inputs'!$C$25 -> -2.1405384 | F11: Cost eaten on failed orders
A12: CONTRIBUTION PER ORDER | B12: =B6+B7+B8+B9+B10+B11 -> 212.7746 | C12: =C6+C7+C8+C9+C10+C11 -> 180.74656 | D12: =D6+D7+D8+D9+D10+D11 -> 132.60803 | E12: =E6+E7+E8+E9+E10+E11 -> 84.430916 | F12: sum of above
A13: Margin % | B13: =B12/B6 -> 0.63896277 | C13: =C12/C6 -> 0.60289047 | D13: =D12/D6 -> 0.53064439 | E13: =E12/E6 -> 0.42223903 | F13: contribution / user price
A14: TOTAL PROFIT per pack sold | B14: =B12*B5 -> 638.32381 | C14: =C12*C5 -> 903.73282 | D14: =D12*D5 -> 1326.0803 | E14: =E12*E5 -> 2110.7729
A16: Comparison: model says vs handbook v3.2 says
A17: Old Pack A/B/C/D pricing (DEPRECATED) | B17: 0.64 | C17: 0.53 | D17: 0.52 | E17: 0.52 | F17: Old prices ₹999/7, ₹1,999/18 etc — REPLACED
A18: This model says | B18: =B13 -> 0.63896277 | C18: =C13 -> 0.60289047 | D18: =D13 -> 0.53064439 | E18: =E13 -> 0.42223903 | F18: Real margin after all real costs
A19: Δ (model - handbook) | B19: =B18-B17 -> -0.0010372261 | C19: =C18-C17 -> 0.072890473 | D19: =D18-D17 -> 0.010644393 | E19: =E18-E17 -> -0.097760974 | F19: Negative = handbook overstated margin
A26: ⭐ LAUNCH PRICING MARGIN VERIFICATION
A27: New pack | B27: Per-order revenue | C27: AI cost (current) | D27: All-in cost | E27: Contribution | F27: Margin %
A28: Starter (₹999/3) | B28: 333 | C28: ='3. API Cost Reality'!$E$22 -> 56.329958 | D28: =C28+B28*'2. Inputs'!$C$48+'4. Fixed Costs'!$B$12/100+'3. API Cost Reality'!$E$21*'2. Inputs'!$C$25 -> 120.2254 | E28: =B28-D28 -> 212.7746 | F28: =E28/B28 -> 0.63896277
A29: Regular (₹1,499/5) | B29: 299.8 | C29: ='3. API Cost Reality'!$E$22 -> 56.329958 | D29: =C29+B29*'2. Inputs'!$C$48+'4. Fixed Costs'!$B$12/100+'3. API Cost Reality'!$E$21*'2. Inputs'!$C$25 -> 119.05344 | E29: =B29-D29 -> 180.74656 | F29: =E29/B29 -> 0.60289047
A30: Pro (₹2,499/10) | B30: 249.9 | C30: ='3. API Cost Reality'!$E$22 -> 56.329958 | D30: =C30+B30*'2. Inputs'!$C$48+'4. Fixed Costs'!$B$12/100+'3. API Cost Reality'!$E$21*'2. Inputs'!$C$25 -> 117.29197 | E30: =B30-D30 -> 132.60803 | F30: =E30/B30 -> 0.53064439
A32: ⚠ NOTE: At current AI cost (₹56/order with regen+failure buffer), all 3 launch packs should show POSITIVE contribution.
A33: Track real production cost in Sheet 12 — if real cost stays below ₹100/order, all packs are profitable.

Sheet 6. Free Trial Burn
A1: FREE TRIAL BURN · Cost of acquiring users at different conversion rates
A3: Trial burn cost = Free signups × Free credits × AI cost per order
A5: Free signups in month | B5: Free credits per user | C5: AI cost per order | D5: Total burn (₹) | E5: Conversion rate | F5: Paid users acquired | G5: CAC per paid user (₹)
A6: 10 | B6: ='2. Inputs'!$C$55 -> 1 | C6: ='3. API Cost Reality'!$E$21 -> 42.810768 | D6: =A6*B6*C6 -> 428.10768 | E6: 0.1 | F6: =A6*E6 -> 1 | G6: =IF(F6=0,0,D6/F6) -> 428.10768
A7: 50 | B7: ='2. Inputs'!$C$55 -> 1 | C7: ='3. API Cost Reality'!$E$21 -> 42.810768 | D7: =A7*B7*C7 -> 2140.5384 | E7: 0.2 | F7: =A7*E7 -> 10 | G7: =IF(F7=0,0,D7/F7) -> 214.05384
A8: 50 | B8: ='2. Inputs'!$C$55 -> 1 | C8: ='3. API Cost Reality'!$E$21 -> 42.810768 | D8: =A8*B8*C8 -> 2140.5384 | E8: 0.3 | F8: =A8*E8 -> 15 | G8: =IF(F8=0,0,D8/F8) -> 142.70256
A9: 100 | B9: ='2. Inputs'!$C$55 -> 1 | C9: ='3. API Cost Reality'!$E$21 -> 42.810768 | D9: =A9*B9*C9 -> 4281.0768 | E9: 0.2 | F9: =A9*E9 -> 20 | G9: =IF(F9=0,0,D9/F9) -> 214.05384
A10: 100 | B10: ='2. Inputs'!$C$55 -> 1 | C10: ='3. API Cost Reality'!$E$21 -> 42.810768 | D10: =A10*B10*C10 -> 4281.0768 | E10: 0.3 | F10: =A10*E10 -> 30 | G10: =IF(F10=0,0,D10/F10) -> 142.70256
A11: 100 | B11: ='2. Inputs'!$C$55 -> 1 | C11: ='3. API Cost Reality'!$E$21 -> 42.810768 | D11: =A11*B11*C11 -> 4281.0768 | E11: 0.5 | F11: =A11*E11 -> 50 | G11: =IF(F11=0,0,D11/F11) -> 85.621536
A12: 500 | B12: ='2. Inputs'!$C$55 -> 1 | C12: ='3. API Cost Reality'!$E$21 -> 42.810768 | D12: =A12*B12*C12 -> 21405.384 | E12: 0.2 | F12: =A12*E12 -> 100 | G12: =IF(F12=0,0,D12/F12) -> 214.05384
A13: 500 | B13: ='2. Inputs'!$C$55 -> 1 | C13: ='3. API Cost Reality'!$E$21 -> 42.810768 | D13: =A13*B13*C13 -> 21405.384 | E13: 0.3 | F13: =A13*E13 -> 150 | G13: =IF(F13=0,0,D13/F13) -> 142.70256
A16: Implication
A17: At 30% conversion (your assumption), CAC from free trial alone:
A18: free credits × AI cost per order ÷ conversion rate
A19: 3 × ~₹35 ÷ 0.30 = ~₹350 per paid user from API burn alone
A21: Add founder time CAC:
A22: founder hours per user × ₹/hour | B22: ='2. Inputs'!$C$66*'2. Inputs'!$C$65 -> 2000
A23: TOTAL CAC per paid user (free-trial cost + founder time) | B23: =B22+(B14) -> 2000

Sheet 7. 12-Month P&L
A1: 12-MONTH P&L · Three scenarios
A3: § CONSERVATIVE SCENARIO
A4: Metric | B4: M1 | C4: M2 | D4: M3 | E4: M4 | F4: M5 | G4: M6 | H4: M7 | I4: M8 | J4: M9 | K4: M10 | L4: M11 | M4: M12 | N4: Year Total
A5: Active paying users | B5: 1 | C5: 1 | D5: 2 | E5: 3 | F5: 4 | G5: 5 | H5: 7 | I5: 9 | J5: 11 | K5: 13 | L5: 16 | M5: 20 | N5: =AVERAGE(B5:M5) -> 7.6666667
A6: Orders generated | B6: =B5*0+B5*'2. Inputs'!$C$54 -> 12 | C6: =B5*0+C5*'2. Inputs'!$C$54 -> 12 | D6: =B5*0+D5*'2. Inputs'!$C$54 -> 24 | E6: =B5*0+E5*'2. Inputs'!$C$54 -> 36 | F6: =B5*0+F5*'2. Inputs'!$C$54 -> 48 | G6: =B5*0+G5*'2. Inputs'!$C$54 -> 60 | H6: =B5*0+H5*'2. Inputs'!$C$54 -> 84 | I6: =B5*0+I5*'2. Inputs'!$C$54 -> 108 | J6: =B5*0+J5*'2. Inputs'!$C$54 -> 132 | K6: =B5*0+K5*'2. Inputs'!$C$54 -> 156 | L6: =B5*0+L5*'2. Inputs'!$C$54 -> 192 | M6: =B5*0+M5*'2. Inputs'!$C$54 -> 240 | N6: =SUM(B6:M6) -> 1104
A7: Avg revenue per order (₹) | B7: ='5. Unit Economics'!$B$6*'2. Inputs'!$C$58+'5. Unit Economics'!$C$6*'2. Inputs'!$C$59+'5. Unit Economics'!$D$6*'2. Inputs'!$C$60+'5. Unit Economics'!$E$6*'2. Inputs'!$C$61 -> 303.1 | C7: ='5. Unit Economics'!$B$6*'2. Inputs'!$C$58+'5. Unit Economics'!$C$6*'2. Inputs'!$C$59+'5. Unit Economics'!$D$6*'2. Inputs'!$C$60+'5. Unit Economics'!$E$6*'2. Inputs'!$C$61 -> 303.1 | D7: ='5. Unit Economics'!$B$6*'2. Inputs'!$C$58+'5. Unit Economics'!$C$6*'2. Inputs'!$C$59+'5. Unit Economics'!$D$6*'2. Inputs'!$C$60+'5. Unit Economics'!$E$6*'2. Inputs'!$C$61 -> 303.1 | E7: ='5. Unit Economics'!$B$6*'2. Inputs'!$C$58+'5. Unit Economics'!$C$6*'2. Inputs'!$C$59+'5. Unit Economics'!$D$6*'2. Inputs'!$C$60+'5. Unit Economics'!$E$6*'2. Inputs'!$C$61 -> 303.1 | F7: ='5. Unit Economics'!$B$6*'2. Inputs'!$C$58+'5. Unit Economics'!$C$6*'2. Inputs'!$C$59+'5. Unit Economics'!$D$6*'2. Inputs'!$C$60+'5. Unit Economics'!$E$6*'2. Inputs'!$C$61 -> 303.1 | G7: ='5. Unit Economics'!$B$6*'2. Inputs'!$C$58+'5. Unit Economics'!$C$6*'2. Inputs'!$C$59+'5. Unit Economics'!$D$6*'2. Inputs'!$C$60+'5. Unit Economics'!$E$6*'2. Inputs'!$C$61 -> 303.1 | H7: ='5. Unit Economics'!$B$6*'2. Inputs'!$C$58+'5. Unit Economics'!$C$6*'2. Inputs'!$C$59+'5. Unit Economics'!$D$6*'2. Inputs'!$C$60+'5. Unit Economics'!$E$6*'2. Inputs'!$C$61 -> 303.1 | I7: ='5. Unit Economics'!$B$6*'2. Inputs'!$C$58+'5. Unit Economics'!$C$6*'2. Inputs'!$C$59+'5. Unit Economics'!$D$6*'2. Inputs'!$C$60+'5. Unit Economics'!$E$6*'2. Inputs'!$C$61 -> 303.1 | ... M7: ='5. Unit Economics'!$B$6*'2. Inputs'!$C$58+'5. Unit Economics'!$C$6*'2. Inputs'!$C$59+'5. Unit Economics'!$D$6*'2. Inputs'!$C$60+'5. Unit Economics'!$E$6*'2. Inputs'!$C$61 -> 303.1 | N7: =B7 -> 303.1
A8: Revenue (gross ₹) | B8: =B6*B7 -> 3637.2 | C8: =C6*C7 -> 3637.2 | D8: =D6*D7 -> 7274.4 | E8: =E6*E7 -> 10911.6 | F8: =F6*F7 -> 14548.8 | G8: =G6*G7 -> 18186 | H8: =H6*H7 -> 25460.4 | I8: =I6*I7 -> 32734.8 | ... M8: =M6*M7 -> 72744 | N8: =SUM(B8:M8) -> 334622.4
A9: AI cost (₹) | B9: =B6*'3. API Cost Reality'!$E$22 -> 675.95949 | C9: =C6*'3. API Cost Reality'!$E$22 -> 675.95949 | D9: =D6*'3. API Cost Reality'!$E$22 -> 1351.919 | E9: =E6*'3. API Cost Reality'!$E$22 -> 2027.8785 | F9: =F6*'3. API Cost Reality'!$E$22 -> 2703.838 | G9: =G6*'3. API Cost Reality'!$E$22 -> 3379.7975 | H9: =H6*'3. API Cost Reality'!$E$22 -> 4731.7165 | I9: =I6*'3. API Cost Reality'!$E$22 -> 6083.6355 | ... M9: =M6*'3. API Cost Reality'!$E$22 -> 13519.19 | N9: =SUM(B9:M9) -> 62188.274
A10: Razorpay fees (₹) | B10: =B8*'2. Inputs'!$C$48 -> 128.39316 | C10: =C8*'2. Inputs'!$C$48 -> 128.39316 | D10: =D8*'2. Inputs'!$C$48 -> 256.78632 | E10: =E8*'2. Inputs'!$C$48 -> 385.17948 | F10: =F8*'2. Inputs'!$C$48 -> 513.57264 | G10: =G8*'2. Inputs'!$C$48 -> 641.9658 | H10: =H8*'2. Inputs'!$C$48 -> 898.75212 | I10: =I8*'2. Inputs'!$C$48 -> 1155.5384 | ... M10: =M8*'2. Inputs'!$C$48 -> 2567.8632 | N10: =SUM(B10:M10) -> 11812.171
A11: GST remitted (₹) | B11: =B8*'2. Inputs'!$C$50/(1+'2. Inputs'!$C$50)*'2. Inputs'!$C$49 -> 0 | C11: =C8*'2. Inputs'!$C$50/(1+'2. Inputs'!$C$50)*'2. Inputs'!$C$49 -> 0 | D11: =D8*'2. Inputs'!$C$50/(1+'2. Inputs'!$C$50)*'2. Inputs'!$C$49 -> 0 | E11: =E8*'2. Inputs'!$C$50/(1+'2. Inputs'!$C$50)*'2. Inputs'!$C$49 -> 0 | F11: =F8*'2. Inputs'!$C$50/(1+'2. Inputs'!$C$50)*'2. Inputs'!$C$49 -> 0 | G11: =G8*'2. Inputs'!$C$50/(1+'2. Inputs'!$C$50)*'2. Inputs'!$C$49 -> 0 | H11: =H8*'2. Inputs'!$C$50/(1+'2. Inputs'!$C$50)*'2. Inputs'!$C$49 -> 0 | I11: =I8*'2. Inputs'!$C$50/(1+'2. Inputs'!$C$50)*'2. Inputs'!$C$49 -> 0 | ... M11: =M8*'2. Inputs'!$C$50/(1+'2. Inputs'!$C$50)*'2. Inputs'!$C$49 -> 0 | N11: =SUM(B11:M11) -> 0
A12: Fixed monthly costs (₹) | B12: ='4. Fixed Costs'!$B$12 -> 5000 | C12: ='4. Fixed Costs'!$B$12 -> 5000 | D12: ='4. Fixed Costs'!$B$12 -> 5000 | E12: ='4. Fixed Costs'!$B$12 -> 5000 | F12: ='4. Fixed Costs'!$B$12 -> 5000 | G12: ='4. Fixed Costs'!$B$12 -> 5000 | H12: ='4. Fixed Costs'!$B$12 -> 5000 | I12: ='4. Fixed Costs'!$B$12 -> 5000 | ... M12: ='4. Fixed Costs'!$B$12 -> 5000 | N12: =SUM(B12:M12) -> 60000
A13: Pre-tax profit (₹) | B13: =B8-B9-B10-B11-B12 -> -2167.1527 | C13: =C8-C9-C10-C11-C12 -> -2167.1527 | D13: =D8-D9-D10-D11-D12 -> 665.69469 | E13: =E8-E9-E10-E11-E12 -> 3498.542 | F13: =F8-F9-F10-F11-F12 -> 6331.3894 | G13: =G8-G9-G10-G11-G12 -> 9164.2367 | H13: =H8-H9-H10-H11-H12 -> 14829.931 | I13: =I8-I9-I10-I11-I12 -> 20495.626 | ... M13: =M8-M9-M10-M11-M12 -> 51656.947 | N13: =SUM(B13:M13) -> 200621.96
A14: Cumulative profit (₹) | B14: =B13 -> -2167.1527 | C14: =B14+C13 -> -4334.3053 | D14: =C14+D13 -> -3668.6106 | E14: =D14+E13 -> -170.06858 | F14: =E14+F13 -> 6161.3208 | G14: =F14+G13 -> 15325.558 | H14: =G14+H13 -> 30155.489 | I14: =H14+I13 -> 50651.115 | J14: =I14+J13 -> 76812.436 | ... M14: =L14+M13 -> 200621.96 | N14: =M14 -> 200621.96
A16: § BASE SCENARIO
A17: Metric | B17: M1 | C17: M2 | D17: M3 | E17: M4 | F17: M5 | G17: M6 | H17: M7 | I17: M8 | J17: M9 | K17: M10 | L17: M11 | M17: M12 | N17: Year Total
A18: Active paying users | B18: 1 | C18: 2 | D18: 4 | E18: 6 | F18: 9 | G18: 12 | H18: 16 | I18: 21 | J18: 27 | K18: 34 | L18: 42 | M18: 50 | N18: =AVERAGE(B18:M18) -> 18.666667
A19: Orders generated | B19: =B18*0+B18*'2. Inputs'!$C$54 -> 12 | C19: =B18*0+C18*'2. Inputs'!$C$54 -> 24 | D19: =B18*0+D18*'2. Inputs'!$C$54 -> 48 | E19: =B18*0+E18*'2. Inputs'!$C$54 -> 72 | F19: =B18*0+F18*'2. Inputs'!$C$54 -> 108 | G19: =B18*0+G18*'2. Inputs'!$C$54 -> 144 | H19: =B18*0+H18*'2. Inputs'!$C$54 -> 192 | I19: =B18*0+I18*'2. Inputs'!$C$54 -> 252 | J19: =B18*0+J18*'2. Inputs'!$C$54 -> 324 | K19: =B18*0+K18*'2. Inputs'!$C$54 -> 408 | L19: =B18*0+L18*'2. Inputs'!$C$54 -> 504 | M19: =B18*0+M18*'2. Inputs'!$C$54 -> 600 | N19: =SUM(B19:M19) -> 2688
A20: Avg revenue per order (₹) | B20: ='5. Unit Economics'!$B$6*'2. Inputs'!$C$58+'5. Unit Economics'!$C$6*'2. Inputs'!$C$59+'5. Unit Economics'!$D$6*'2. Inputs'!$C$60+'5. Unit Economics'!$E$6*'2. Inputs'!$C$61 -> 303.1 | C20: ='5. Unit Economics'!$B$6*'2. Inputs'!$C$58+'5. Unit Economics'!$C$6*'2. Inputs'!$C$59+'5. Unit Economics'!$D$6*'2. Inputs'!$C$60+'5. Unit Economics'!$E$6*'2. Inputs'!$C$61 -> 303.1 | D20: ='5. Unit Economics'!$B$6*'2. Inputs'!$C$58+'5. Unit Economics'!$C$6*'2. Inputs'!$C$59+'5. Unit Economics'!$D$6*'2. Inputs'!$C$60+'5. Unit Economics'!$E$6*'2. Inputs'!$C$61 -> 303.1 | E20: ='5. Unit Economics'!$B$6*'2. Inputs'!$C$58+'5. Unit Economics'!$C$6*'2. Inputs'!$C$59+'5. Unit Economics'!$D$6*'2. Inputs'!$C$60+'5. Unit Economics'!$E$6*'2. Inputs'!$C$61 -> 303.1 | F20: ='5. Unit Economics'!$B$6*'2. Inputs'!$C$58+'5. Unit Economics'!$C$6*'2. Inputs'!$C$59+'5. Unit Economics'!$D$6*'2. Inputs'!$C$60+'5. Unit Economics'!$E$6*'2. Inputs'!$C$61 -> 303.1 | G20: ='5. Unit Economics'!$B$6*'2. Inputs'!$C$58+'5. Unit Economics'!$C$6*'2. Inputs'!$C$59+'5. Unit Economics'!$D$6*'2. Inputs'!$C$60+'5. Unit Economics'!$E$6*'2. Inputs'!$C$61 -> 303.1 | H20: ='5. Unit Economics'!$B$6*'2. Inputs'!$C$58+'5. Unit Economics'!$C$6*'2. Inputs'!$C$59+'5. Unit Economics'!$D$6*'2. Inputs'!$C$60+'5. Unit Economics'!$E$6*'2. Inputs'!$C$61 -> 303.1 | I20: ='5. Unit Economics'!$B$6*'2. Inputs'!$C$58+'5. Unit Economics'!$C$6*'2. Inputs'!$C$59+'5. Unit Economics'!$D$6*'2. Inputs'!$C$60+'5. Unit Economics'!$E$6*'2. Inputs'!$C$61 -> 303.1 | ... M20: ='5. Unit Economics'!$B$6*'2. Inputs'!$C$58+'5. Unit Economics'!$C$6*'2. Inputs'!$C$59+'5. Unit Economics'!$D$6*'2. Inputs'!$C$60+'5. Unit Economics'!$E$6*'2. Inputs'!$C$61 -> 303.1 | N20: =B20 -> 303.1
A21: Revenue (gross ₹) | B21: =B19*B20 -> 3637.2 | C21: =C19*C20 -> 7274.4 | D21: =D19*D20 -> 14548.8 | E21: =E19*E20 -> 21823.2 | F21: =F19*F20 -> 32734.8 | G21: =G19*G20 -> 43646.4 | H21: =H19*H20 -> 58195.2 | I21: =I19*I20 -> 76381.2 | ... M21: =M19*M20 -> 181860 | N21: =SUM(B21:M21) -> 814732.8
A22: AI cost (₹) | B22: =B19*'3. API Cost Reality'!$E$22 -> 675.95949 | C22: =C19*'3. API Cost Reality'!$E$22 -> 1351.919 | D22: =D19*'3. API Cost Reality'!$E$22 -> 2703.838 | E22: =E19*'3. API Cost Reality'!$E$22 -> 4055.757 | F22: =F19*'3. API Cost Reality'!$E$22 -> 6083.6355 | G22: =G19*'3. API Cost Reality'!$E$22 -> 8111.5139 | H22: =H19*'3. API Cost Reality'!$E$22 -> 10815.352 | I22: =I19*'3. API Cost Reality'!$E$22 -> 14195.149 | ... M22: =M19*'3. API Cost Reality'!$E$22 -> 33797.975 | N22: =SUM(B22:M22) -> 151414.93
A23: Razorpay fees (₹) | B23: =B21*'2. Inputs'!$C$48 -> 128.39316 | C23: =C21*'2. Inputs'!$C$48 -> 256.78632 | D23: =D21*'2. Inputs'!$C$48 -> 513.57264 | E23: =E21*'2. Inputs'!$C$48 -> 770.35896 | F23: =F21*'2. Inputs'!$C$48 -> 1155.5384 | G23: =G21*'2. Inputs'!$C$48 -> 1540.7179 | H23: =H21*'2. Inputs'!$C$48 -> 2054.2906 | I23: =I21*'2. Inputs'!$C$48 -> 2696.2564 | ... M23: =M21*'2. Inputs'!$C$48 -> 6419.658 | N23: =SUM(B23:M23) -> 28760.068
A24: GST remitted (₹) | B24: =B21*'2. Inputs'!$C$50/(1+'2. Inputs'!$C$50)*'2. Inputs'!$C$49 -> 0 | C24: =C21*'2. Inputs'!$C$50/(1+'2. Inputs'!$C$50)*'2. Inputs'!$C$49 -> 0 | D24: =D21*'2. Inputs'!$C$50/(1+'2. Inputs'!$C$50)*'2. Inputs'!$C$49 -> 0 | E24: =E21*'2. Inputs'!$C$50/(1+'2. Inputs'!$C$50)*'2. Inputs'!$C$49 -> 0 | F24: =F21*'2. Inputs'!$C$50/(1+'2. Inputs'!$C$50)*'2. Inputs'!$C$49 -> 0 | G24: =G21*'2. Inputs'!$C$50/(1+'2. Inputs'!$C$50)*'2. Inputs'!$C$49 -> 0 | H24: =H21*'2. Inputs'!$C$50/(1+'2. Inputs'!$C$50)*'2. Inputs'!$C$49 -> 0 | I24: =I21*'2. Inputs'!$C$50/(1+'2. Inputs'!$C$50)*'2. Inputs'!$C$49 -> 0 | ... M24: =M21*'2. Inputs'!$C$50/(1+'2. Inputs'!$C$50)*'2. Inputs'!$C$49 -> 0 | N24: =SUM(B24:M24) -> 0
A25: Fixed monthly costs (₹) | B25: ='4. Fixed Costs'!$B$12 -> 5000 | C25: ='4. Fixed Costs'!$B$12 -> 5000 | D25: ='4. Fixed Costs'!$B$12 -> 5000 | E25: ='4. Fixed Costs'!$B$12 -> 5000 | F25: ='4. Fixed Costs'!$B$12 -> 5000 | G25: ='4. Fixed Costs'!$B$12 -> 5000 | H25: ='4. Fixed Costs'!$B$12 -> 5000 | I25: ='4. Fixed Costs'!$B$12 -> 5000 | ... M25: ='4. Fixed Costs'!$B$12 -> 5000 | N25: =SUM(B25:M25) -> 60000
A26: Pre-tax profit (₹) | B26: =B21-B22-B23-B24-B25 -> -2167.1527 | C26: =C21-C22-C23-C24-C25 -> 665.69469 | D26: =D21-D22-D23-D24-D25 -> 6331.3894 | E26: =E21-E22-E23-E24-E25 -> 11997.084 | F26: =F21-F22-F23-F24-F25 -> 20495.626 | G26: =G21-G22-G23-G24-G25 -> 28994.168 | H26: =H21-H22-H23-H24-H25 -> 40325.558 | I26: =I21-I22-I23-I24-I25 -> 54489.794 | ... M26: =M21-M22-M23-M24-M25 -> 136642.37 | N26: =SUM(B26:M26) -> 574557.81
A27: Cumulative profit (₹) | B27: =B26 -> -2167.1527 | C27: =B27+C26 -> -1501.458 | D27: =C27+D26 -> 4829.9314 | E27: =D27+E26 -> 16827.015 | F27: =E27+F26 -> 37322.642 | G27: =F27+G26 -> 66316.81 | H27: =G27+H26 -> 106642.37 | I27: =H27+I26 -> 161132.16 | J27: =I27+J26 -> 232619.04 | ... M27: =L27+M26 -> 574557.81 | N27: =M27 -> 574557.81
A29: § UPSIDE SCENARIO
A30: Metric | B30: M1 | C30: M2 | D30: M3 | E30: M4 | F30: M5 | G30: M6 | H30: M7 | I30: M8 | J30: M9 | K30: M10 | L30: M11 | M30: M12 | N30: Year Total
A31: Active paying users | B31: 1 | C31: 3 | D31: 7 | E31: 12 | F31: 18 | G31: 26 | H31: 36 | I31: 50 | J31: 70 | K31: 95 | L31: 130 | M31: 175 | N31: =AVERAGE(B31:M31) -> 51.916667
A32: Orders generated | B32: =B31*0+B31*'2. Inputs'!$C$54 -> 12 | C32: =B31*0+C31*'2. Inputs'!$C$54 -> 36 | D32: =B31*0+D31*'2. Inputs'!$C$54 -> 84 | E32: =B31*0+E31*'2. Inputs'!$C$54 -> 144 | F32: =B31*0+F31*'2. Inputs'!$C$54 -> 216 | G32: =B31*0+G31*'2. Inputs'!$C$54 -> 312 | H32: =B31*0+H31*'2. Inputs'!$C$54 -> 432 | I32: =B31*0+I31*'2. Inputs'!$C$54 -> 600 | J32: =B31*0+J31*'2. Inputs'!$C$54 -> 840 | K32: =B31*0+K31*'2. Inputs'!$C$54 -> 1140 | L32: =B31*0+L31*'2. Inputs'!$C$54 -> 1560 | M32: =B31*0+M31*'2. Inputs'!$C$54 -> 2100 | N32: =SUM(B32:M32) -> 7476
A33: Avg revenue per order (₹) | B33: ='5. Unit Economics'!$B$6*'2. Inputs'!$C$58+'5. Unit Economics'!$C$6*'2. Inputs'!$C$59+'5. Unit Economics'!$D$6*'2. Inputs'!$C$60+'5. Unit Economics'!$E$6*'2. Inputs'!$C$61 -> 303.1 | C33: ='5. Unit Economics'!$B$6*'2. Inputs'!$C$58+'5. Unit Economics'!$C$6*'2. Inputs'!$C$59+'5. Unit Economics'!$D$6*'2. Inputs'!$C$60+'5. Unit Economics'!$E$6*'2. Inputs'!$C$61 -> 303.1 | D33: ='5. Unit Economics'!$B$6*'2. Inputs'!$C$58+'5. Unit Economics'!$C$6*'2. Inputs'!$C$59+'5. Unit Economics'!$D$6*'2. Inputs'!$C$60+'5. Unit Economics'!$E$6*'2. Inputs'!$C$61 -> 303.1 | E33: ='5. Unit Economics'!$B$6*'2. Inputs'!$C$58+'5. Unit Economics'!$C$6*'2. Inputs'!$C$59+'5. Unit Economics'!$D$6*'2. Inputs'!$C$60+'5. Unit Economics'!$E$6*'2. Inputs'!$C$61 -> 303.1 | F33: ='5. Unit Economics'!$B$6*'2. Inputs'!$C$58+'5. Unit Economics'!$C$6*'2. Inputs'!$C$59+'5. Unit Economics'!$D$6*'2. Inputs'!$C$60+'5. Unit Economics'!$E$6*'2. Inputs'!$C$61 -> 303.1 | G33: ='5. Unit Economics'!$B$6*'2. Inputs'!$C$58+'5. Unit Economics'!$C$6*'2. Inputs'!$C$59+'5. Unit Economics'!$D$6*'2. Inputs'!$C$60+'5. Unit Economics'!$E$6*'2. Inputs'!$C$61 -> 303.1 | H33: ='5. Unit Economics'!$B$6*'2. Inputs'!$C$58+'5. Unit Economics'!$C$6*'2. Inputs'!$C$59+'5. Unit Economics'!$D$6*'2. Inputs'!$C$60+'5. Unit Economics'!$E$6*'2. Inputs'!$C$61 -> 303.1 | I33: ='5. Unit Economics'!$B$6*'2. Inputs'!$C$58+'5. Unit Economics'!$C$6*'2. Inputs'!$C$59+'5. Unit Economics'!$D$6*'2. Inputs'!$C$60+'5. Unit Economics'!$E$6*'2. Inputs'!$C$61 -> 303.1 | ... M33: ='5. Unit Economics'!$B$6*'2. Inputs'!$C$58+'5. Unit Economics'!$C$6*'2. Inputs'!$C$59+'5. Unit Economics'!$D$6*'2. Inputs'!$C$60+'5. Unit Economics'!$E$6*'2. Inputs'!$C$61 -> 303.1 | N33: =B33 -> 303.1
A34: Revenue (gross ₹) | B34: =B32*B33 -> 3637.2 | C34: =C32*C33 -> 10911.6 | D34: =D32*D33 -> 25460.4 | E34: =E32*E33 -> 43646.4 | F34: =F32*F33 -> 65469.6 | G34: =G32*G33 -> 94567.2 | H34: =H32*H33 -> 130939.2 | I34: =I32*I33 -> 181860 | ... M34: =M32*M33 -> 636510 | N34: =SUM(B34:M34) -> 2265975.6
A35: AI cost (₹) | B35: =B32*'3. API Cost Reality'!$E$22 -> 675.95949 | C35: =C32*'3. API Cost Reality'!$E$22 -> 2027.8785 | D35: =D32*'3. API Cost Reality'!$E$22 -> 4731.7165 | E35: =E32*'3. API Cost Reality'!$E$22 -> 8111.5139 | F35: =F32*'3. API Cost Reality'!$E$22 -> 12167.271 | G35: =G32*'3. API Cost Reality'!$E$22 -> 17574.947 | H35: =H32*'3. API Cost Reality'!$E$22 -> 24334.542 | I35: =I32*'3. API Cost Reality'!$E$22 -> 33797.975 | ... M35: =M32*'3. API Cost Reality'!$E$22 -> 118292.91 | N35: =SUM(B35:M35) -> 421122.77
A36: Razorpay fees (₹) | B36: =B34*'2. Inputs'!$C$48 -> 128.39316 | C36: =C34*'2. Inputs'!$C$48 -> 385.17948 | D36: =D34*'2. Inputs'!$C$48 -> 898.75212 | E36: =E34*'2. Inputs'!$C$48 -> 1540.7179 | F36: =F34*'2. Inputs'!$C$48 -> 2311.0769 | G36: =G34*'2. Inputs'!$C$48 -> 3338.2222 | H36: =H34*'2. Inputs'!$C$48 -> 4622.1538 | I36: =I34*'2. Inputs'!$C$48 -> 6419.658 | ... M36: =M34*'2. Inputs'!$C$48 -> 22468.803 | N36: =SUM(B36:M36) -> 79988.939
A37: GST remitted (₹) | B37: =B34*'2. Inputs'!$C$50/(1+'2. Inputs'!$C$50)*'2. Inputs'!$C$49 -> 0 | C37: =C34*'2. Inputs'!$C$50/(1+'2. Inputs'!$C$50)*'2. Inputs'!$C$49 -> 0 | D37: =D34*'2. Inputs'!$C$50/(1+'2. Inputs'!$C$50)*'2. Inputs'!$C$49 -> 0 | E37: =E34*'2. Inputs'!$C$50/(1+'2. Inputs'!$C$50)*'2. Inputs'!$C$49 -> 0 | F37: =F34*'2. Inputs'!$C$50/(1+'2. Inputs'!$C$50)*'2. Inputs'!$C$49 -> 0 | G37: =G34*'2. Inputs'!$C$50/(1+'2. Inputs'!$C$50)*'2. Inputs'!$C$49 -> 0 | H37: =H34*'2. Inputs'!$C$50/(1+'2. Inputs'!$C$50)*'2. Inputs'!$C$49 -> 0 | I37: =I34*'2. Inputs'!$C$50/(1+'2. Inputs'!$C$50)*'2. Inputs'!$C$49 -> 0 | ... M37: =M34*'2. Inputs'!$C$50/(1+'2. Inputs'!$C$50)*'2. Inputs'!$C$49 -> 0 | N37: =SUM(B37:M37) -> 0
A38: Fixed monthly costs (₹) | B38: ='4. Fixed Costs'!$B$12 -> 5000 | C38: ='4. Fixed Costs'!$B$12 -> 5000 | D38: ='4. Fixed Costs'!$B$12 -> 5000 | E38: ='4. Fixed Costs'!$B$12 -> 5000 | F38: ='4. Fixed Costs'!$B$12 -> 5000 | G38: ='4. Fixed Costs'!$B$12 -> 5000 | H38: ='4. Fixed Costs'!$B$12 -> 5000 | I38: ='4. Fixed Costs'!$B$12 -> 5000 | ... M38: ='4. Fixed Costs'!$B$12 -> 5000 | N38: =SUM(B38:M38) -> 60000
A39: Pre-tax profit (₹) | B39: =B34-B35-B36-B37-B38 -> -2167.1527 | C39: =C34-C35-C36-C37-C38 -> 3498.542 | D39: =D34-D35-D36-D37-D38 -> 14829.931 | E39: =E34-E35-E36-E37-E38 -> 28994.168 | F39: =F34-F35-F36-F37-F38 -> 45991.252 | G39: =G34-G35-G36-G37-G38 -> 68654.031 | H39: =H34-H35-H36-H37-H38 -> 96982.504 | I39: =I34-I35-I36-I37-I38 -> 136642.37 | ... M39: =M34-M35-M36-M37-M38 -> 490748.29 | N39: =SUM(B39:M39) -> 1704863.9
A40: Cumulative profit (₹) | B40: =B39 -> -2167.1527 | C40: =B40+C39 -> 1331.3894 | D40: =C40+D39 -> 16161.321 | E40: =D40+E39 -> 45155.489 | F40: =E40+F39 -> 91146.741 | G40: =F40+G39 -> 159800.77 | H40: =G40+H39 -> 256783.28 | I40: =H40+I39 -> 393425.64 | J40: =I40+J39 -> 586724.96 | ... M40: =L40+M39 -> 1704863.9 | N40: =M40 -> 1704863.9

Sheet 8. Break-Even
A1: BREAK-EVEN ANALYSIS · How many users do we need?
A3: Break-even at different AI cost scenarios
A4: AI cost per order | B4: Avg revenue per order | C4: Variable cost per order | D4: Contribution per order | E4: Fixed cost / month | F4: Orders needed / month | G4: Users needed (12 orders/user)
A5: Best case (₹15) | B5: ='5. Unit Economics'!$B$6*'2. Inputs'!$C$58+'5. Unit Economics'!$C$6*'2. Inputs'!$C$59+'5. Unit Economics'!$D$6*'2. Inputs'!$C$60+'5. Unit Economics'!$E$6*'2. Inputs'!$C$61 -> 303.1 | C5: =15+B5*'2. Inputs'!$C$48 -> 25.69943 | D5: =B5-C5 -> 277.40057 | E5: ='4. Fixed Costs'!$B$12 -> 5000 | F5: =IF(D5<=0,9999,E5/D5) -> 18.024476 | G5: =F5/'2. Inputs'!$C$54 -> 1.5020397
A6: Realistic blended (₹25) | B6: ='5. Unit Economics'!$B$6*'2. Inputs'!$C$58+'5. Unit Economics'!$C$6*'2. Inputs'!$C$59+'5. Unit Economics'!$D$6*'2. Inputs'!$C$60+'5. Unit Economics'!$E$6*'2. Inputs'!$C$61 -> 303.1 | C6: =25+B6*'2. Inputs'!$C$48 -> 35.69943 | D6: =B6-C6 -> 267.40057 | E6: ='4. Fixed Costs'!$B$12 -> 5000 | F6: =IF(D6<=0,9999,E6/D6) -> 18.698539 | G6: =F6/'2. Inputs'!$C$54 -> 1.5582116
A7: Current model (₹35) | B7: ='5. Unit Economics'!$B$6*'2. Inputs'!$C$58+'5. Unit Economics'!$C$6*'2. Inputs'!$C$59+'5. Unit Economics'!$D$6*'2. Inputs'!$C$60+'5. Unit Economics'!$E$6*'2. Inputs'!$C$61 -> 303.1 | C7: =35+B7*'2. Inputs'!$C$48 -> 45.69943 | D7: =B7-C7 -> 257.40057 | E7: ='4. Fixed Costs'!$B$12 -> 5000 | F7: =IF(D7<=0,9999,E7/D7) -> 19.424976 | G7: =F7/'2. Inputs'!$C$54 -> 1.618748
A8: With regen buffer (₹50) | B8: ='5. Unit Economics'!$B$6*'2. Inputs'!$C$58+'5. Unit Economics'!$C$6*'2. Inputs'!$C$59+'5. Unit Economics'!$D$6*'2. Inputs'!$C$60+'5. Unit Economics'!$E$6*'2. Inputs'!$C$61 -> 303.1 | C8: =50+B8*'2. Inputs'!$C$48 -> 60.69943 | D8: =B8-C8 -> 242.40057 | E8: ='4. Fixed Costs'!$B$12 -> 5000 | F8: =IF(D8<=0,9999,E8/D8) -> 20.627014 | G8: =F8/'2. Inputs'!$C$54 -> 1.7189179
A9: Worst case (₹70) | B9: ='5. Unit Economics'!$B$6*'2. Inputs'!$C$58+'5. Unit Economics'!$C$6*'2. Inputs'!$C$59+'5. Unit Economics'!$D$6*'2. Inputs'!$C$60+'5. Unit Economics'!$E$6*'2. Inputs'!$C$61 -> 303.1 | C9: =70+B9*'2. Inputs'!$C$48 -> 80.69943 | D9: =B9-C9 -> 222.40057 | E9: ='4. Fixed Costs'!$B$12 -> 5000 | F9: =IF(D9<=0,9999,E9/D9) -> 22.481957 | G9: =F9/'2. Inputs'!$C$54 -> 1.8734964
A10: Anthropic prices double (₹100) | B10: ='5. Unit Economics'!$B$6*'2. Inputs'!$C$58+'5. Unit Economics'!$C$6*'2. Inputs'!$C$59+'5. Unit Economics'!$D$6*'2. Inputs'!$C$60+'5. Unit Economics'!$E$6*'2. Inputs'!$C$61 -> 303.1 | C10: =100+B10*'2. Inputs'!$C$48 -> 110.69943 | D10: =B10-C10 -> 192.40057 | E10: ='4. Fixed Costs'!$B$12 -> 5000 | F10: =IF(D10<=0,9999,E10/D10) -> 25.987449 | G10: =F10/'2. Inputs'!$C$54 -> 2.1656207
A13: Compared to handbook claim
A14: Handbook v3.2 says: | B14: Break-even at ~10 users in month 5
A15: This model says: | B15: =G7 & " users at ₹35/order AI cost" -> 1.61874803411145 users at ₹35/order AI cost
A16: Risk: | B16: If AI cost ends up at ₹50 (with regen buffer), need ~ users

Sheet 9. CAC + LTV
A1: CUSTOMER ACQUISITION COST & LIFETIME VALUE
A3: A. Customer Acquisition Cost (CAC)
A4: Founder hours per acquired user | B4: ='2. Inputs'!$C$66 -> 4 | C4: hours | D4: Demos, follow-up, onboarding
A5: Founder time value per hour | B5: ='2. Inputs'!$C$65 -> 500 | C5: ₹/hour | D5: Civil engineering opportunity cost
A6: Founder time CAC | B6: ='2. Inputs'!$C$66*'2. Inputs'!$C$65 -> 2000 | C6: ₹ | D6: hours × rate
A7: Free-trial API burn per converted user | B7: ='2. Inputs'!$C$55*'3. API Cost Reality'!$E$21/'2. Inputs'!$C$56 -> 142.70256 | C7: ₹ | D7: 3 credits × AI cost ÷ conversion rate
A8: TOTAL CAC per paid user | B8: =B6+B7 -> 2142.7026 | C8: ₹ | D8: founder time + trial burn
A11: B. Lifetime Value (LTV)
A12: Avg orders per active user per month | B12: ='2. Inputs'!$C$54 -> 12 | C12: orders/mo
A13: Avg user retention | B13: ='2. Inputs'!$C$57 -> 9 | C13: months | D13: Karnataka transfer cycle
A14: Total orders per user lifetime | B14: =B12*B13 -> 108 | C14: orders | D14: orders × months
A15: Avg revenue per order | B15: ='5. Unit Economics'!$B$6*'2. Inputs'!$C$58+'5. Unit Economics'!$C$6*'2. Inputs'!$C$59+'5. Unit Economics'!$D$6*'2. Inputs'!$C$60+'5. Unit Economics'!$E$6*'2. Inputs'!$C$61 -> 303.1 | C15: ₹ | D15: Weighted by pack mix
A16: Avg contribution per order | B16: ='5. Unit Economics'!$B$12*'2. Inputs'!$C$58+'5. Unit Economics'!$C$12*'2. Inputs'!$C$59+'5. Unit Economics'!$D$12*'2. Inputs'!$C$60+'5. Unit Economics'!$E$12*'2. Inputs'!$C$61 -> 183.93007 | C16: ₹ | D16: Net of variable costs
A17: LIFETIME VALUE per user | B17: =B14*B16 -> 19864.448 | C17: ₹ | D17: orders × contribution
A19: C. LTV / CAC ratio
A20: LTV / CAC ratio | B20: =B17/B8 -> 9.2707445
A21: Healthy SaaS benchmark | B21: > 3x
A22: Verdict | B22: =IF(B20>=3,"Healthy",IF(B20>=1,"Marginal — improve CAC or LTV","Unsustainable")) -> Healthy

Sheet 10. Pricing Decisions
A1: PRICING DECISIONS · Should we change prices?
A3: ⭐ LOCKED LAUNCH PRICING DECISION (April 27, 2026)
A4: Decision rationale: Launch with 3 simple tiers + 1 free order. Hide Bulk/Power until production data proves real per-order cost.
A6: Pack | B6: Orders | C6: Price | D6: Per order | E6: Launch? | F6: Notes
A7: Trial | B7: 1 | C7: 0 | D7: 0 | E7: ✅ LAUNCH | F7: First order free; classic SaaS conversion driver
A8: Starter | B8: 3 | C8: 999 | D8: 333 | E8: ✅ LAUNCH | F8: Cheapest entry; expected 40% of users
A9: Regular | B9: 5 | C9: 1499 | D9: 300 | E9: ✅ LAUNCH | F9: Best value perception; expected 40% of users
A10: Pro | B10: 10 | C10: 2499 | D10: 250 | E10: ✅ LAUNCH | F10: Heavy users; expected 20% of users
A11: Bulk | B11: 25 | C11: 4999 | D11: 200 | E11: ⏳ HIDDEN | F11: Unlock after 20-30 paid orders show real cost
A12: Power | B12: 50 | C12: 8999 | D12: 180 | E12: ⏳ HIDDEN | F12: Unlock after Bulk validated for 1 month
A14: Approved marketing language:
A15: "Human drafters usually cost ₹1,000–₹2,000 per order.
A16: Aadesh pilot packs reduce the effective cost to ₹250–₹333 per order."
A18: Do NOT say: "Orders start at ₹500" — anchors at fake single-order price.
A20: Conditions to unlock Bulk pack (₹4,999/25):
A21: 1. 20-30 paid orders generated and tracked in Sheet 12
A22: 2. Real cost/order known and stable
A23: 3. No bulk-pack abuse pattern observed
A24: 4. Support burden manageable (<5 min/order)
A26: Decision B: Should complex PDFs cost 2 credits?
A27: Reason | B27: Bigger PDFs use more PDF Vision tokens (linearly), so cost scales with pages
A28: Threshold suggestion | B28: PDFs over 50 pages → 2 credits
A29: Implementation | B29: Detect page count at upload; show user "this is a long case, will use 2 credits"
A31: Decision C: When to register GST?
A32: Handbook says | B32: Register at ₹15 lakh (proactive, not the legal ₹20 lakh)
A33: At Pack B avg ₹999 | B33: ₹15L / ₹999 = ~1500 packs sold = ~22,500 orders
A34: At what user count | B34: ~125 users × 12 orders/mo × 12 months = 18,000 orders/year — close to threshold at year 1
A35: Recommendation | B35: Register before crossing ₹15L. Set GST flag in Inputs sheet to 1 to model post-GST P&L.
A37: Decision D: Should office plan exist?
A38: One officer pays Pack D (₹4,999 / 120 orders / ₹42 per order) | B38: But shares login with 5 colleagues
A39: Effective revenue per order | B39: ₹4,999 ÷ 120 = ₹42/order — but 5 users used those credits
A40: Implication | B40: You miss out on ₹4,999 × 4 = ₹19,996 of revenue
A41: Solution | B41: Office plan: ₹15,000 / 5 users / 600 orders / ₹25 per order. Higher revenue, lower per-order cost shared.
A43: Decision E: Pack D is loss-making at current price (CRITICAL)
A44: Current Pack D price (live) | B44: ₹4,999 / 120 orders = ₹41.66/order
A45: Real cost per order (model + buffer) | B45: ='3. API Cost Reality'!$E$22 -> 56.329958
A46: Margin at current price | B46: LOSS of ~₹68/order = ~₹8,160 lost per Pack D sold
A47: My recommendation: Re-price Pack D to ₹7,999 / 100 orders | B47: Per-order: ₹80, margin: +30% (profitable)
A48: Conservative alternative: ₹9,999 / 100 orders | B48: Per-order: ₹100, margin: +44%
A49: ChatGPT recommendation: Pause Pack D entirely | B49: Until production cost data confirms <₹25/order
...

Sheet 11. CRITICAL FINDINGS
A1: 🚨 CRITICAL FINDINGS · Issues uncovered while building this model
A3: # | B3: Issue | C3: Severity | D3: Action required
A4: ⭐ | B4: LAUNCH PRICING LOCKED (April 27, 2026) Trial: 1 free order. Starter: 3/₹999. Regular: 5/₹1,499. Pro: 10/₹2,499. Bulk and Power packs HIDDEN until 20-30 paid orders prove real cost. Marketing: "Human drafters cost ₹1,000-2,000/order; Aadesh ₹250-333/order." | C4: RESOLVED | D4: Razorpay store needs update: pause Pack A/B/C/D, add Starter/Regular/Pro, hide Bulk/Power. Generate Claude Code prompt.
A6: 1 | B6: Handbook v3.2 pricing does NOT match live Razorpay prices. Handbook shows: Pack A ₹999/7, B ₹1999/18, C ₹3499/32, D ₹5999/55. Razorpay live: Pack A ₹499/5, B ₹999/15, C ₹1999/40, D ₹4999/120. Razorpay version is what users actually see and pay. | C6: CRITICAL | D6: Decide which is correct, fix the other. Update handbook BEFORE RAI submission.
A7: 2 | B7: Real per-order cost from $50 testing spend = ~$0.81/order (~₹64) — much higher than ₹24 model claim. $23.45 spent ÷ 29 test orders = $0.81/order. Production should be cheaper (cache hits, no thinking mode), but testing data shows we burn fast on iteration. | C7: HIGH | D7: Track production per-order cost daily. If real >₹40, raise pricing or change model.
A8: 3 | B8: Free trial of 3 credits at 30% conversion = ~₹350 CAC from API burn alone. Plus ~₹2,000 founder time CAC (4 hours × ₹500/hour). Real CAC ≈ ₹2,350/user — needs verification. | C8: HIGH | D8: Either reduce free credits to 2, or raise conversion rate via better demo, or accept the CAC.
A9: 4 | B9: Karnataka officer transfers happen every 1-2 years. Assumed retention of 9 months. This is a hard ceiling on LTV. When officer transfers → Aadesh setup is wiped. | C9: MEDIUM | D9: Build Transfer Mode well — make it easy to start fresh at new posting.
A10: 5 | B10: GST registration at ₹15L revenue threshold reduces effective revenue by ~15% (₹999 → ₹847). Doc shows margins pre-GST. Post-GST margins drop materially. | C10: MEDIUM | D10: Plan for GST timing. Set GST flag in this model to 1 to see post-GST scenarios.
A11: 6 | B11: Anthropic API price is set in USD. ₹/USD volatility directly affects per-order cost. A 10% INR depreciation = 10% direct AI cost increase, no warning. | C11: MEDIUM | D11: Hedge by holding 3-month USD budget; or pass through via per-pack pricing.
A12: 7 | B12: Single AI vendor dependency (Anthropic). If they raise prices 50%, current margins compress to dangerous levels. Sarvam fallback is 91/100 quality vs 96/100 — usable but not equivalent. | C12: MEDIUM | D12: Keep Sarvam path warm. Test quality regularly. Have a "switch in 24 hours" plan.
A13: 8 | B13: Founder time is unmodeled in current handbook P&L. 40 hours/week × ₹500 notional = ₹80,000/month opportunity cost. Year 1 net is ₹1.4 lakh "profit" — but that ignores founder labor. True economic profit is negative until ~50 paying users. | C13: MEDIUM | D13: Decide when founder starts drawing salary. Plan for that month in cashflow.
A14: 9 | B14: Handbook says "0 paying users today" and "break-even at 10 users month 5". But this assumes month 1 gets to 1 user, month 2 → 2, month 3 → 4, etc. At zero acquisition channels live (no ads, only word of mouth), this growth is optimistic. | C14: MEDIUM | D14: Validate growth assumption with first 3 paying users in 3 months. If misses, adjust.
A15: 10 | B15: No model fallback strategy is costed. If Sonnet fails, switch to Sarvam = ₹0 AI cost but 91/100 quality. Could be PROFIT BOOSTER if some orders work fine on Sarvam. Not modeled. | C15: OPPORTUNITY | D15: Test Sarvam quality on simple cases. Auto-route simple → Sarvam, complex → Sonnet. Could lift margins 10-20%.
A16: 11 | B16: Office plan is missing from pricing sheet. A single Pack D (₹4,999) shared by 5 colleagues = revenue loss of ₹20K. Office plan at ₹15,000/5 users would capture this. | C16: OPPORTUNITY | D16: Design Office Plan v1 for Phase 2. Capture team purchases.
A17: 12 | B17: Quality benchmark says 89.2% live, 98% best lab. But we have not measured officer acceptance rate (signs without rewriting). AI quality and signature acceptance are different metrics. | C17: CRITICAL DATA GAP | D17: After Banu signs first 3 real orders, measure edit distance from AI draft to final signed version.
... A21: 16 | B21: Pack D at ₹4,999/120 orders = ₹41.66/order is loss-making at any reasonable AI cost. Model says: contribution is −₹68/order = ~₹8,160 lost per Pack D sold. ChatGPT says: pause it. I say: re-price to ₹7,999/100 orders (₹80/order = +30% margin). | C21: CRITICAL | D21: Re-price Pack D BEFORE next user signs up. See Sheet 10 Decision E for options.

Sheet 12. Live Cost Tracker
A1: LIVE COST TRACKER · Populate with real production orders
A2: ChatGPT correction: production cost MUST be tracked separately from R&D testing cost. Add one row per real order.
A4: Date | B4: Order ID | C4: User | D4: Model | E4: Input tokens | F4: Output tokens | G4: Cache read | H4: Cache write | I4: API cost (USD) | J4: API cost (₹) | K4: Pack price/order | L4: Margin (₹) | M4: Notes
J5: =I5*'2. Inputs'!$C$9*(1+'2. Inputs'!$C$10) -> 0 | L5: =K5-J5 -> 0
J6: =I6*'2. Inputs'!$C$9*(1+'2. Inputs'!$C$10) -> 0 | L6: =K6-J6 -> 0
J7: =I7*'2. Inputs'!$C$9*(1+'2. Inputs'!$C$10) -> 0 | L7: =K7-J7 -> 0
J8: =I8*'2. Inputs'!$C$9*(1+'2. Inputs'!$C$10) -> 0 | L8: =K8-J8 -> 0
J9: =I9*'2. Inputs'!$C$9*(1+'2. Inputs'!$C$10) -> 0 | L9: =K9-J9 -> 0
J10: =I10*'2. Inputs'!$C$9*(1+'2. Inputs'!$C$10) -> 0 | L10: =K10-J10 -> 0
J11: =I11*'2. Inputs'!$C$9*(1+'2. Inputs'!$C$10) -> 0 | L11: =K11-J11 -> 0
J12: =I12*'2. Inputs'!$C$9*(1+'2. Inputs'!$C$10) -> 0 | L12: =K12-J12 -> 0
J13: =I13*'2. Inputs'!$C$9*(1+'2. Inputs'!$C$10) -> 0 | L13: =K13-J13 -> 0
J14: =I14*'2. Inputs'!$C$9*(1+'2. Inputs'!$C$10) -> 0 | L14: =K14-J14 -> 0
J15: =I15*'2. Inputs'!$C$9*(1+'2. Inputs'!$C$10) -> 0 | L15: =K15-J15 -> 0
J16: =I16*'2. Inputs'!$C$9*(1+'2. Inputs'!$C$10) -> 0 | L16: =K16-J16 -> 0
... J24: =I24*'2. Inputs'!$C$9*(1+'2. Inputs'!$C$10) -> 0 | L24: =K24-J24 -> 0
A27: SUMMARY
A28: Number of orders tracked | B28: =COUNTA(A5:A24) -> 0
A29: Total API cost (₹) | B29: =SUM(J5:J24) -> 0
A30: Average cost per order (₹) | B30: =IFERROR(B29/B28,0) -> 0
A31: Total margin captured (₹) | B31: =SUM(L5:L24) -> 0
A33: ⚠ Update Sheet 2 row "Production cost per order (live measured)" with B30 once 10+ orders tracked

Sheet 13. Office Plans
A1: OFFICE PLAN ECONOMICS · Capture team purchases
A2: Captures the shared-login leak. Office plans are your scale path beyond individual subscriptions.
A4: Metric | B4: Pack D (1 user) | C4: Office Pilot | D4: Office Standard | E4: Office District | F4: Notes
A5: Monthly price | B5: ='2. Inputs'!$C$44 -> 4999 | C5: ='2. Inputs'!$C$95 -> 2999 | D5: ='2. Inputs'!$C$98 -> 4999 | E5: ='2. Inputs'!$C$101 -> 9999 | F5: Pack D is one-time pack; offices are monthly
A6: Users covered | B6: 1 | C6: ='2. Inputs'!$C$96 -> 5 | D6: ='2. Inputs'!$C$99 -> 10 | E6: ='2. Inputs'!$C$102 -> 20
A7: Orders pool | B7: ='2. Inputs'!$C$45 -> 25 | C7: ='2. Inputs'!$C$97 -> 100 | D7: ='2. Inputs'!$C$100 -> 200 | E7: ='2. Inputs'!$C$103 -> 500
A9: Effective price per order | B9: =B5/B7 -> 199.96 | C9: =C5/C7 -> 29.99 | D9: =D5/D7 -> 24.995 | E9: =E5/E7 -> 19.998
A10: AI cost per order | B10: ='3. API Cost Reality'!$E$22 -> 56.329958 | C10: ='3. API Cost Reality'!$E$22 -> 56.329958 | D10: ='3. API Cost Reality'!$E$22 -> 56.329958 | E10: ='3. API Cost Reality'!$E$22 -> 56.329958
A11: Razorpay/payment fee | B11: =B9*'2. Inputs'!$C$48 -> 7.058588 | C11: =C9*'2. Inputs'!$C$48 -> 1.058647 | D11: =D9*'2. Inputs'!$C$48 -> 0.8823235 | E11: =E9*'2. Inputs'!$C$48 -> 0.7059294
A12: Contribution per order | B12: =B9-B10-B11 -> 136.57145 | C12: =C9-C10-C11 -> -27.398605 | D12: =D9-D10-D11 -> -32.217281 | E12: =E9-E10-E11 -> -37.037887
A13: Margin % | B13: =B12/B9 -> 0.68299387 | C13: =C12/C9 -> -0.91359136 | D13: =D12/D9 -> -1.288949 | E13: =E12/E9 -> -1.8520796
A15: SHARED-LOGIN LEAKAGE COMPARISON
A16: Scenario A: 5 colleagues share one Pack D
A17: Revenue captured | B17: ='2. Inputs'!$C$44 -> 4999 | C17: ₹4,999 once
A18: Scenario B: Office Pilot covers same 5 colleagues
A19: Revenue captured (per month) | B19: ='2. Inputs'!$C$95 -> 2999 | C19: ₹2,999/mo recurring → ₹35,988/year
A20: 12-month delta (Office vs Pack D) | B20: ='2. Inputs'!$C$95*12-'2. Inputs'!$C$44 -> 30989 | C20: Revenue capture from same office
A22: RECOMMENDATION
A23: Launch Office Pilot plan when 3+ users from the same office sign up.
A24: Office plans capture team purchases that individual packs cannot.
A25: Pricing here is illustrative — validate with first office customer before publishing.
